Workbook

Sheet Sales Transactions
A1: Date | B1: Item | C1: Category | D1: Sale Price | E1: Actual Profit | F1: Calories
A2: 44562 | B2: Beer | C2: Beverages | D2: 4 | E2: =D2-VLOOKUP('Item Look Up Table'!$A$2,'Item Look Up Table'!$A$2:$B$15,2,FALSE) -> 2 | F2: =VLOOKUP('Item Look Up Table'!$A$2,'Item Look Up Table'!$A$1:$C$15,3,FALSE) -> 200 | H2: Day: | I2: Total Profit: | J2: Percentage of Sales by Day: | L2: Day: | M2: Total Calories: | N2: Percentage by Day: | P2: Row Labels | Q2: Count
A3: 44562 | B3: Hamburger | C3: Hot Food | D3: 3 | E3: =D3-VLOOKUP('Item Look Up Table'!$A$7,'Item Look Up Table'!$A$2:$B$15,2,FALSE) -> 1.5 | F3: =VLOOKUP('Item Look Up Table'!$A$7,'Item Look Up Table'!$A$1:$C$15,3,FALSE) -> 320 | H3: 44562 | I3: =SUMIFS(E:E,A:A,"<="&"1/1/2022",A:A,">="&"1/1/2022") -> 28 | J3: =I3/$I$12 -> 0.086687307 | L3: 44562 | M3: =SUMIFS(F:F,A:A,"<="&"1/1/2022",A:A,">="&"1/1/2022") -> 4295 | N3: =M3/$M$12 -> 0.074026198 | P3: Beer | Q3: 20
A4: 44562 | B4: Popcorn | C4: Hot Food | D4: 5 | E4: =D4-VLOOKUP('Item Look Up Table'!$A$13,'Item Look Up Table'!$A$2:$B$15,2,FALSE) -> 4.5 | F4: =VLOOKUP('Item Look Up Table'!$A$13,'Item Look Up Table'!$A$1:$C$15,3,FALSE) -> 500 | H4: 44563 | I4: =SUMIFS(E:E,A:A,"<="&"1/2/2022",A:A,">="&"1/2/2022") -> 55.5 | J4: =I4/$I$12 -> 0.17182663 | L4: 44563 | M4: =SUMIFS(F:F,A:A,"<="&"1/2/2022",A:A,">="&"1/2/2022") -> 9280 | N4: =M4/$M$12 -> 0.15994485 | P4: Bottled Water | Q4: 13
A5: 44562 | B5: Soda | C5: Beverages | D5: 2.5 | E5: =D5-VLOOKUP('Item Look Up Table'!$A$15,'Item Look Up Table'!$A$2:$B$15,2,FALSE) -> 1.5 | F5: =VLOOKUP('Item Look Up Table'!$A$15,'Item Look Up Table'!$A$1:$C$15,3,FALSE) -> 120 | H5: 44564 | I5: =SUMIFS(E:E,A:A,"<="&"1/3/2022",A:A,">="&"1/3/2022") -> 18.5 | J5: =I5/$I$12 -> 0.057275542 | L5: 44564 | M5: =SUMIFS(F:F,A:A,"<="&"1/3/2022",A:A,">="&"1/3/2022") -> 5165 | N5: =M5/$M$12 -> 0.089021027 | P5: Chocolate Bar | Q5: 13
A6: 44562 | B6: Gummy Bears | C6: Candy | D6: 2 | E6: =D6-VLOOKUP('Item Look Up Table'!$A$6,'Item Look Up Table'!$A$2:B$15,2,FALSE) -> 0 | F6: =VLOOKUP('Item Look Up Table'!$A$6,'Item Look Up Table'!$A$1:$C$15,3,FALSE) -> 300 | H6: 44565 | I6: =SUMIFS(E:E,A:A,"<="&"1/4/2022",A:A,">="&"1/4/2022") -> 19.5 | J6: =I6/$I$12 -> 0.060371517 | L6: 44565 | M6: =SUMIFS(F:F,A:A,"<="&"1/4/2022",A:A,">="&"1/4/2022") -> 4585 | N6: =M6/$M$12 -> 0.079024474 | P6: Chocolate Dipped Cone | Q6: 11
A7: 44562 | B7: Chocolate Dipped Cone | C7: Frozen Treats | D7: 3 | E7: =D7-VLOOKUP('Item Look Up Table'!$A$5,'Item Look Up Table'!$A$2:B$15,2,FALSE) -> 2 | F7: =VLOOKUP('Item Look Up Table'!$A$5,'Item Look Up Table'!$A$1:$C$15,3,FALSE) -> 300 | H7: 44566 | I7: =SUMIFS(E:E,A:A,"<="&"1/5/2022",A:A,">="&"1/5/2022") -> 0 | J7: =I7/$I$12 -> 0 | L7: 44566 | M7: =SUMIFS(F:F,A:A,"<="&"1/5/2022",A:A,">="&"1/5/2022") -> 0 | N7: =M7/$M$12 -> 0 | P7: Gummy Bears | Q7: 14
A8: 44562 | B8: Soda | C8: Beverages | D8: 2.5 | E8: =D8-VLOOKUP('Item Look Up Table'!$A$15,'Item Look Up Table'!$A$2:$B$15,2,FALSE) -> 1.5 | F8: =VLOOKUP('Item Look Up Table'!$A$15,'Item Look Up Table'!$A$1:$C$15,3,FALSE) -> 120 | H8: 44567 | I8: =SUMIFS(E:E,A:A,"<="&"1/6/2022",A:A,">="&"1/6/2022") -> 79.5 | J8: =I8/$I$12 -> 0.24613003 | L8: 44567 | M8: =SUMIFS(F:F,A:A,"<="&"1/6/2022",A:A,">="&"1/6/2022") -> 12565 | N8: =M8/$M$12 -> 0.21656325 | P8: Hamburger | Q8: 16
A9: 44562 | B9: Hot Dog | C9: Hot Food | D9: 1.5 | E9: =D9-VLOOKUP('Item Look Up Table'!$A$8,'Item Look Up Table'!$A$2:$B$15,2,FALSE) -> 1 | F9: =VLOOKUP('Item Look Up Table'!$A$8,'Item Look Up Table'!$A$1:$C$15,3,FALSE) -> 265 | H9: 44568 | I9: =SUMIFS(E:E,A:A,"<="&"1/7/2022",A:A,">="&"1/7/2022") -> 48 | J9: =I9/$I$12 -> 0.14860681 | L9: 44568 | M9: =SUMIFS(F:F,A:A,"<="&"1/7/2022",A:A,">="&"1/7/2022") -> 10910 | N9: =M9/$M$12 -> 0.18803861 | P9: Hot Dog | Q9: 15
A10: 44562 | B10: Pizza | C10: Hot Food | D10: 2 | E10: =D10-VLOOKUP('Item Look Up Table'!$A$12,'Item Look Up Table'!$A$2:$B$15,2,FALSE) -> 1 | F10: =VLOOKUP('Item Look Up Table'!$A$12,'Item Look Up Table'!$A$1:$C$15,3,FALSE) -> 480 | H10: 44569 | I10: =SUMIFS(E:E,A:A,"<="&"1/8/2022",A:A,">="&"1/8/2022") -> 38 | J10: =I10/$I$12 -> 0.11764706 | L10: 44569 | M10: =SUMIFS(F:F,A:A,"<="&"1/8/2022",A:A,">="&"1/8/2022") -> 6275 | N10: =M10/$M$12 -> 0.10815236 | P10: Ice Cream Sandwich | Q10: 10
A11: 44562 | B11: Nachos | C11: Hot Food | D11: 3 | E11: =D11-VLOOKUP('Item Look Up Table'!$A$11,'Item Look Up Table'!$A$2:$B$15,2,FALSE) -> 0.5 | F11: =VLOOKUP('Item Look Up Table'!$A$11,'Item Look Up Table'!$A$1:$C$15,3,FALSE) -> 560 | H11: 44570 | I11: =SUMIFS(E:E,A:A,"<="&"1/9/2022",A:A,">="&"1/9/2022") -> 36 | J11: =I11/$I$12 -> 0.11145511 | L11: 44570 | M11: =SUMIFS(F:F,A:A,"<="&"1/9/2022",A:A,">="&"1/9/2022") -> 4945 | N11: =M11/$M$12 -> 0.085229231 | P11: Licorice Rope | Q11: 13
A12: 44562 | B12: Bottled Water | C12: Beverages | D12: 3 | E12: =D12-VLOOKUP('Item Look Up Table'!$A$3,'Item Look Up Table'!$A$2:B$15,2,FALSE) -> 2.5 | F12: =VLOOKUP('Item Look Up Table'!$A$3,'Item Look Up Table'!$A$1:$C$15,3,FALSE) -> 0 | H12: Total: | I12: =SUM(I3:I11) -> 323 | J12: =SUM(J3:J11) -> 1 | L12: Total: | M12: =SUM(M3:M11) -> 58020 | N12: =SUM(N3:N11) -> 1 | P12: Nachos | Q12: 15
A13: 44562 | B13: Beer | C13: Beverages | D13: 4 | E13: =D13-VLOOKUP('Item Look Up Table'!$A$2,'Item Look Up Table'!$A$2:$B$15,2,FALSE) -> 2 | F13: =VLOOKUP('Item Look Up Table'!$A$2,'Item Look Up Table'!$A$1:$C$15,3,FALSE) -> 200 | P13: Pizza | Q13: 17
A14: 44562 | B14: Licorice Rope | C14: Candy | D14: 2 | E14: =D14-VLOOKUP('Item Look Up Table'!$A$10,'Item Look Up Table'!$A$2:$B$15,2,FALSE) -> 1 | F14: =VLOOKUP('Item Look Up Table'!$A$10,'Item Look Up Table'!$A$1:$C$15,3,FALSE) -> 280 | P14: Popcorn | Q14: 16
A15: 44562 | B15: Popsicle | C15: Frozen Treats | D15: 3 | E15: =D15-VLOOKUP('Item Look Up Table'!$A$14,'Item Look Up Table'!$A$2:$B$15,2,FALSE) -> 2.5 | F15: =VLOOKUP('Item Look Up Table'!$A$14,'Item Look Up Table'!$A$1:$C$15,3,FALSE) -> 150 | P15: Popsicle | Q15: 13
A16: 44562 | B16: Popcorn | C16: Hot Food | D16: 5 | E16: =D16-VLOOKUP('Item Look Up Table'!$A$13,'Item Look Up Table'!$A$2:$B$15,2,FALSE) -> 4.5 | F16: =VLOOKUP('Item Look Up Table'!$A$13,'Item Look Up Table'!$A$1:$C$15,3,FALSE) -> 500 | H16: Item: | I16: Total Profit: | J16: Percentage of Total Sales: | L16: Item: | M16: Total Calories: | N16: Percentage by Item: | P16: Soda | Q16: 13
A17: 44563 | B17: Pizza | C17: Hot Food | D17: 2 | E17: =D17-VLOOKUP('Item Look Up Table'!$A$12,'Item Look Up Table'!$A$2:$B$15,2,FALSE) -> 1 | F17: =VLOOKUP('Item Look Up Table'!$A$12,'Item Look Up Table'!$A$1:$C$15,3,FALSE) -> 480 | H17: Beer | I17: =SUMIF(B:B,"Beer",E:E) -> 40 | J17: =I17/$I$31 -> 0.12383901 | L17: Beer | M17: =SUMIF(B:B,"Beer",F:F) -> 4000 | N17: =M17/$M$31 -> 0.068941744 | P17: Grand Total | Q17: 199
A18: 44563 | B18: Bottled Water | C18: Beverages | D18: 3 | E18: =D18-VLOOKUP('Item Look Up Table'!$A$3,'Item Look Up Table'!$A$2:B$15,2,FALSE) -> 2.5 | F18: =VLOOKUP('Item Look Up Table'!$A$3,'Item Look Up Table'!$A$1:$C$15,3,FALSE) -> 0 | H18: Bottled Water | I18: =SUMIF(B:B,"Bottled Water",E:E) -> 32.5 | J18: =I18/$I$31 -> 0.1006192 | L18: Bottled Water | M18: =SUMIF(B:B,"Bottled Water",F:F) -> 0 | N18: =M18/$M$31 -> 0
A19: 44563 | B19: Hot Dog | C19: Hot Food | D19: 1.5 | E19: =D19-VLOOKUP('Item Look Up Table'!$A$8,'Item Look Up Table'!$A$2:$B$15,2,FALSE) -> 1 | F19: =VLOOKUP('Item Look Up Table'!$A$8,'Item Look Up Table'!$A$1:$C$15,3,FALSE) -> 265 | H19: Chocolate Bar | I19: =SUMIF(B:B,"Chocolate Bar",E:E) -> 13 | J19: =I19/$I$31 -> 0.040247678 | L19: Chocolate Bar | M19: =SUMIF(B:B,"Chocolate Bar",F:F) -> 3315 | N19: =M19/$M$31 -> 0.057135471
A20: 44563 | B20: Chocolate Dipped Cone | C20: Frozen Treats | D20: 3 | E20: =D20-VLOOKUP('Item Look Up Table'!$A$5,'Item Look Up Table'!$A$2:B$15,2,FALSE) -> 2 | F20: =VLOOKUP('Item Look Up Table'!$A$5,'Item Look Up Table'!$A$1:$C$15,3,FALSE) -> 300 | H20: Chocolate Dipped Cone | I20: =SUMIF(B:B,"Chocolate Dipped Cone",E:E) -> 22 | J20: =I20/$I$31 -> 0.068111455 | L20: Chocolate Dipped Cone | M20: =SUMIF(B:B,"Chocolate Dipped Cone",F:F) -> 3300 | N20: =M20/$M$31 -> 0.056876939 | P20: Row Labels | Q20: Count
A21: 44563 | B21: Soda | C21: Beverages | D21: 2.5 | E21: =D21-VLOOKUP('Item Look Up Table'!$A$15,'Item Look Up Table'!$A$2:$B$15,2,FALSE) -> 1.5 | F21: =VLOOKUP('Item Look Up Table'!$A$15,'Item Look Up Table'!$A$1:$C$15,3,FALSE) -> 120 | H21: Gummy Bears | I21: =SUMIF(B:B,"Gummy Bears",E:E) -> 0 | J21: =I21/$I$31 -> 0 | L21: Gummy Bears | M21: =SUMIF(B:B,"Gummy Bears",F:F) -> 4200 | N21: =M21/$M$31 -> 0.072388831 | P21: Beverages | Q21: 46
A22: 44563 | B22: Chocolate Bar | C22: Candy | D22: 2 | E22: =D22-VLOOKUP('Item Look Up Table'!$A$4,'Item Look Up Table'!$A$2:B$15,2,FALSE) -> 1 | F22: =VLOOKUP('Item Look Up Table'!$A$4,'Item Look Up Table'!$A$1:$C$15,3,FALSE) -> 255 | H22: Hamburger | I22: =SUMIF(B:B,"Hamburger",E:E) -> 24 | J22: =I22/$I$31 -> 0.074303406 | L22: Hamburger | M22: =SUMIF(B:B,"Hamburger",F:F) -> 5120 | N22: =M22/$M$31 -> 0.088245433 | P22: Candy | Q22: 40
A23: 44563 | B23: Hamburger | C23: Hot Food | D23: 3 | E23: =D23-VLOOKUP('Item Look Up Table'!$A$7,'Item Look Up Table'!$A$2:$B$15,2,FALSE) -> 1.5 | F23: =VLOOKUP('Item Look Up Table'!$A$7,'Item Look Up Table'!$A$1:$C$15,3,FALSE) -> 320 | H23: Hot Dog | I23: =SUMIF(B:B,"Hot Dog",E:E) -> 15 | J23: =I23/$I$31 -> 0.046439628 | L23: Hot Dog | M23: =SUMIF(B:B,"Hot Dog",F:F) -> 3975 | N23: =M23/$M$31 -> 0.068510858 | P23: Frozen Treats | Q23: 34
A24: 44563 | B24: Licorice Rope | C24: Candy | D24: 2 | E24: =D24-VLOOKUP('Item Look Up Table'!$A$10,'Item Look Up Table'!$A$2:$B$15,2,FALSE) -> 1 | F24: =VLOOKUP('Item Look Up Table'!$A$10,'Item Look Up Table'!$A$1:$C$15,3,FALSE) -> 280 | H24: Ice Cream Sandwich | I24: =SUMIF(B:B,"Ice Cream Sandwich",E:E) -> 15 | J24: =I24/$I$31 -> 0.046439628 | L24: Ice Cream Sandwich | M24: =SUMIF(B:B,"Ice Cream Sandwich",F:F) -> 2400 | N24: =M24/$M$31 -> 0.041365047 | P24: Hot Food | Q24: 79
A25: 44563 | B25: Nachos | C25: Hot Food | D25: 3 | E25: =D25-VLOOKUP('Item Look Up Table'!$A$11,'Item Look Up Table'!$A$2:$B$15,2,FALSE) -> 0.5 | F25: =VLOOKUP('Item Look Up Table'!$A$11,'Item Look Up Table'!$A$1:$C$15,3,FALSE) -> 560 | H25: Licorice Rope | I25: =SUMIF(B:B,"Licorice Rope",E:E) -> 13 | J25: =I25/$I$31 -> 0.040247678 | L25: Licorice Rope | M25: =SUMIF(B:B,"Licorice Rope",F:F) -> 3640 | N25: =M25/$M$31 -> 0.062736987 | P25: Grand Total | Q25: 199
A26: 44563 | B26: Bottled Water | C26: Beverages | D26: 3 | E26: =D26-VLOOKUP('Item Look Up Table'!$A$3,'Item Look Up Table'!$A$2:B$15,2,FALSE) -> 2.5 | F26: =VLOOKUP('Item Look Up Table'!$A$3,'Item Look Up Table'!$A$1:$C$15,3,FALSE) -> 0 | H26: Nachos | I26: =SUMIF(B:B,"Nachos",E:E) -> 7.5 | J26: =I26/$I$31 -> 0.023219814 | L26: Nachos | M26: =SUMIF(B:B,"Nachos",F:F) -> 8400 | N26: =M26/$M$31 -> 0.14477766
A27: 44563 | B27: Bottled Water | C27: Beverages | D27: 3 | E27: =D27-VLOOKUP('Item Look Up Table'!$A$3,'Item Look Up Table'!$A$2:B$15,2,FALSE) -> 2.5 | F27: =VLOOKUP('Item Look Up Table'!$A$3,'Item Look Up Table'!$A$1:$C$15,3,FALSE) -> 0 | H27: Pizza | I27: =SUMIF(B:B,"Pizza",E:E) -> 17 | J27: =I27/$I$31 -> 0.052631579 | L27: Pizza | M27: =SUMIF(B:B,"Pizza",F:F) -> 8160 | N27: =M27/$M$31 -> 0.14064116
A28: 44563 | B28: Popcorn | C28: Hot Food | D28: 5 | E28: =D28-VLOOKUP('Item Look Up Table'!$A$13,'Item Look Up Table'!$A$2:$B$15,2,FALSE) -> 4.5 | F28: =VLOOKUP('Item Look Up Table'!$A$13,'Item Look Up Table'!$A$1:$C$15,3,FALSE) -> 500 | H28: Popcorn | I28: =SUMIF(B:B,"Popcorn",E:E) -> 72 | J28: =I28/$I$31 -> 0.22291022 | L28: Popcorn | M28: =SUMIF(B:B,"Popcorn",F:F) -> 8000 | N28: =M28/$M$31 -> 0.13788349
A29: 44563 | B29: Chocolate Bar | C29: Candy | D29: 2 | E29: =D29-VLOOKUP('Item Look Up Table'!$A$4,'Item Look Up Table'!$A$2:B$15,2,FALSE) -> 1 | F29: =VLOOKUP('Item Look Up Table'!$A$4,'Item Look Up Table'!$A$1:$C$15,3,FALSE) -> 255 | H29: Popsicle | I29: =SUMIF(B:B,"Popsicle",E:E) -> 32.5 | J29: =I29/$I$31 -> 0.1006192 | L29: Popsicle | M29: =SUMIF(B:B,"Popsicle",F:F) -> 1950 | N29: =M29/$M$31 -> 0.0336091
A30: 44563 | B30: Chocolate Dipped Cone | C30: Frozen Treats | D30: 3 | E30: =D30-VLOOKUP('Item Look Up Table'!$A$5,'Item Look Up Table'!$A$2:B$15,2,FALSE) -> 2 | F30: =VLOOKUP('Item Look Up Table'!$A$5,'Item Look Up Table'!$A$1:$C$15,3,FALSE) -> 300 | H30: Soda | I30: =SUMIF(B:B,"Soda",E:E) -> 19.5 | J30: =I30/$I$31 -> 0.060371517 | L30: Soda | M30: =SUMIF(B:B,"Soda",F:F) -> 1560 | N30: =M30/$M$31 -> 0.02688728
A31: 44563 | B31: Soda | C31: Beverages | D31: 2.5 | E31: =D31-VLOOKUP('Item Look Up Table'!$A$15,'Item Look Up Table'!$A$2:$B$15,2,FALSE) -> 1.5 | F31: =VLOOKUP('Item Look Up Table'!$A$15,'Item Look Up Table'!$A$1:$C$15,3,FALSE) -> 120 | H31: Total: | I31: =SUM(I17:I30) -> 323 | J31: =SUM(J17:J30) -> 1 | L31: Total: | M31: =SUM(M17:M30) -> 58020 | N31: =SUM(N17:N30) -> 1
A32: 44563 | B32: Gummy Bears | C32: Candy | D32: 2 | E32: =D32-VLOOKUP('Item Look Up Table'!$A$6,'Item Look Up Table'!$A$2:B$15,2,FALSE) -> 0 | F32: =VLOOKUP('Item Look Up Table'!$A$6,'Item Look Up Table'!$A$1:$C$15,3,FALSE) -> 300
A33: 44563 | B33: Chocolate Dipped Cone | C33: Frozen Treats | D33: 3 | E33: =D33-VLOOKUP('Item Look Up Table'!$A$5,'Item Look Up Table'!$A$2:B$15,2,FALSE) -> 2 | F33: =VLOOKUP('Item Look Up Table'!$A$5,'Item Look Up Table'!$A$1:$C$15,3,FALSE) -> 300
A34: 44563 | B34: Soda | C34: Beverages | D34: 2.5 | E34: =D34-VLOOKUP('Item Look Up Table'!$A$15,'Item Look Up Table'!$A$2:$B$15,2,FALSE) -> 1.5 | F34: =VLOOKUP('Item Look Up Table'!$A$15,'Item Look Up Table'!$A$1:$C$15,3,FALSE) -> 120
A35: 44563 | B35: Chocolate Bar | C35: Candy | D35: 2 | E35: =D35-VLOOKUP('Item Look Up Table'!$A$4,'Item Look Up Table'!$A$2:B$15,2,FALSE) -> 1 | F35: =VLOOKUP('Item Look Up Table'!$A$4,'Item Look Up Table'!$A$1:$C$15,3,FALSE) -> 255
A36: 44563 | B36: Beer | C36: Beverages | D36: 4 | E36: =D36-VLOOKUP('Item Look Up Table'!$A$2,'Item Look Up Table'!$A$2:$B$15,2,FALSE) -> 2 | F36: =VLOOKUP('Item Look Up Table'!$A$2,'Item Look Up Table'!$A$1:$C$15,3,FALSE) -> 200
A37: 44563 | B37: Chocolate Dipped Cone | C37: Frozen Treats | D37: 3 | E37: =D37-VLOOKUP('Item Look Up Table'!$A$5,'Item Look Up Table'!$A$2:B$15,2,FALSE) -> 2 | F37: =VLOOKUP('Item Look Up Table'!$A$5,'Item Look Up Table'!$A$1:$C$15,3,FALSE) -> 300
A38: 44563 | B38: Hamburger | C38: Hot Food | D38: 3 | E38: =D38-VLOOKUP('Item Look Up Table'!$A$7,'Item Look Up Table'!$A$2:$B$15,2,FALSE) -> 1.5 | F38: =VLOOKUP('Item Look Up Table'!$A$7,'Item Look Up Table'!$A$1:$C$15,3,FALSE) -> 320
A39: 44563 | B39: Chocolate Bar | C39: Candy | D39: 2 | E39: =D39-VLOOKUP('Item Look Up Table'!$A$4,'Item Look Up Table'!$A$2:B$15,2,FALSE) -> 1 | F39: =VLOOKUP('Item Look Up Table'!$A$4,'Item Look Up Table'!$A$1:$C$15,3,FALSE) -> 255
A40: 44563 | B40: Popcorn | C40: Hot Food | D40: 5 | E40: =D40-VLOOKUP('Item Look Up Table'!$A$13,'Item Look Up Table'!$A$2:$B$15,2,FALSE) -> 4.5 | F40: =VLOOKUP('Item Look Up Table'!$A$13,'Item Look Up Table'!$A$1:$C$15,3,FALSE) -> 500
...

Sheet Item Look Up Table
A1: Item | B1: Cost of Goods Sold | C1: Calories
A2: Beer | B2: 2 | C2: 200
A3: Bottled Water | B3: 0.5 | C3: 0
A4: Chocolate Bar | B4: 1 | C4: 255
A5: Chocolate Dipped Cone | B5: 1 | C5: 300
A6: Gummy Bears | B6: 2 | C6: 300
A7: Hamburger | B7: 1.5 | C7: 320
A8: Hot Dog | B8: 0.5 | C8: 265
A9: Ice Cream Sandwich | B9: 1.5 | C9: 240
A10: Licorice Rope | B10: 1 | C10: 280
A11: Nachos | B11: 2.5 | C11: 560
A12: Pizza | B12: 1 | C12: 480
A13: Popcorn | B13: 0.5 | C13: 500
... A15: Soda | B15: 1 | C15: 120
